<?xml version="1.0"?>
<robot name="my_bot">

    <material name="yellow_light">
        <color rgba="1.0 1.0 0.0 0.7"/>
    </material>

    <material name ='wooden'>
        <color rgba='0.76 0.60 0.024 1'/>
    </material>

    <material name ='black'>
        <color rgba='0.0 0.0 0.0 1'/>
    </material>

    <link name="base_link">
    </link>

    <link name="base_footprint">
    </link>
    
    <joint name="footprint_joint" type="fixed">
        <parent link="base_link"/>
        <child link="base_footprint"/>
        <origin xyz="0 0 0" rpy="0 0 0"/>
    </joint>

    <!-- B O D Y -->
    <link name="chassis">
        <visual>
            <geometry>
                <!-- <box size="0.3 0.54 0.15"/> -->
                <box size="0.20 0.3 0.03"/>
            </geometry>
            <material name="wooden"/>
        </visual>

        <collision>
            <geometry>
                <box size="0.20 0.26 0.05"/>
            </geometry>
        </collision>

        <inertial>
            <mass value="0.8"/>
            <origin rpy="0 0 0" xyz="0 0 0"/>
            <inertia ixx="0.0077083333333333335" ixy="0" ixz="0" iyy="0.0035416666666666674" iyz="0" izz="0.015"/>
        </inertial>

    </link>

    <gazebo reference="chassis">
        <material>Gazebo/Yellow</material>
    </gazebo>

    <joint name="base_link_joint" type="fixed">
        <origin rpy="0 0 1.57" xyz="0 0 0" />
        <parent link="base_link" />
        <child link="chassis" />
    </joint>

    <!-- <link name="arm">
        <visual>
            <origin rpy="0 0 1.57" xyz="0 0 0"/>
            <geometry>
                <mesh filename="package://harvester/models/final_arm_model.stl" scale="0.001 0.001 0.001"/>
            </geometry>
            <material name="black"/>
        </visual>

        <collision>
            <origin rpy="0 0 1.57" xyz="0 0 0"/>
            <geometry>
               <mesh filename="package://harvester/models/final_arm_model.stl" scale="0.001 0.001 0.001"/>
            </geometry>
        </collision>

        <inertial>
            <origin rpy="0 0 1.57" xyz="0 0 0"/>
            <mass value="1.2"/>
            <inertia ixx="0.2" ixy="0" ixz="0" iyy="0.2" iyz="0" izz="0.2"/>
        </inertial>
    </link>

    <gazebo reference="arm">
        <material>Gazebo/Blue</material>
    </gazebo>

    <joint name="arm_joint" type="fixed">
        <origin rpy="0 0 1.57" xyz="0 0 0.01" />
        <parent link="chassis" />
        <child link="arm" />
    </joint> -->

    <!--ARM-->
    <link name="arm_base">
        <visual>
            <origin rpy="0 0 1.57" xyz="0 0 0"/>
            <geometry>
                <mesh filename="package://harvester/models/arm/arm_base.stl" scale="0.001 0.001 0.001"/>
            </geometry>
            <material name="black"/>
        </visual>

        <collision>
            <origin rpy="0 0 1.57" xyz="0 0 0"/>
            <geometry>
               <mesh filename="package://harvester/models/arm/arm_base.stl" scale="0.001 0.001 0.001"/>
            </geometry>
        </collision>

        <inertial>
            <origin rpy="0 0 1.57" xyz="0 0 0"/>
            <mass value="0.01"/>
            <inertia ixx="0.005" ixy="0" ixz="0" iyy="0.005" iyz="0" izz="0.005"/>
        </inertial>
    </link>

    <gazebo reference="arm_base">
        <material>Gazebo/Blue</material>
    </gazebo>

    <joint name="arm_base_joint" type="fixed">
        <origin rpy="0 0 1.57" xyz="0 0 0.01" />
        <parent link="chassis" />
        <child link="arm_base" />
    </joint>


    <link name="link_1">
        <visual>
            <origin rpy="0 0 1.57" xyz="0 0 0"/>
            <geometry>
                <mesh filename="package://harvester/models/arm/link1.stl" scale="0.001 0.001 0.001"/>
            </geometry>
            <material name="black"/>
        </visual>

        <collision>
            <origin rpy="0 0 1.57" xyz="0 0 0"/>
            <geometry>
               <mesh filename="package://harvester/models/arm/link1.stl" scale="0.001 0.001 0.001"/>
            </geometry>
        </collision>

        <inertial>
            <origin rpy="0 0 1.57" xyz="0 0 0"/>
            <mass value="0.3"/>
            <inertia ixx="0.005" ixy="0" ixz="0" iyy="0.005" iyz="0" izz="0.005"/>
        </inertial>
    </link>

    <gazebo reference="link_1">
        <material>Gazebo/Blue</material>
    </gazebo>

    <joint name="link_1_joint" type="continuous">
        <origin rpy="1.57 0 0" xyz="0 0 0.04"/>
        <child link="link_1"/>
        <parent link="arm_base"/>
        <axis rpy="0 0 0" xyz="1 0 0"/>
        <limit effort="10000" velocity="1000"/>
        <joint_properties damping="1.0" friction="1.0"/>
    </joint>

    <!--LINK 2-->
    <link name="link_2">
        <visual>
            <origin rpy="0 0 1.57" xyz="0.0 0.0 0.0"/>
            <geometry>
                <mesh filename="package://harvester/models/arm/link2.stl" scale="0.001 0.001 0.001"/>
            </geometry>
            <material name="black"/>
        </visual>

        <collision>
            <origin rpy="0 0 1.57" xyz="0.0 0.0 0.0"/>
            <geometry>
               <mesh filename="package://harvester/models/arm/link2.stl" scale="0.001 0.001 0.001"/>
            </geometry>
        </collision>

        <inertial>
            <origin rpy="0 0 1.57" xyz="0.0 0.0 0.0"/>
            <mass value="0.3"/>
            <inertia ixx="0.005" ixy="0" ixz="0" iyy="0.005" iyz="0" izz="0.005"/>
        </inertial>
    </link>

    <gazebo reference="link_2">
        <material>Gazebo/Blue</material>
    </gazebo>

    <joint name="link_2_joint" type="continuous">
        <origin rpy="2.35 0 0" xyz="0 0.18 0"/>
        <child link="link_2"/>
        <parent link="link_1"/>
        <axis rpy="0 0 0" xyz="1 0 0"/>
        <limit effort="10000" velocity="1000"/>
        <joint_properties damping="1.0" friction="1.0"/>
    </joint>

    <link name="gripper">
        <visual>
            <origin rpy="0 0 1.57" xyz="0.0 0.0 0.0"/>
            <geometry>
                <mesh filename="package://harvester/models/arm/gripper.stl" scale="0.001 0.001 0.001"/>
            </geometry>
            <material name="black"/>
        </visual>

        <collision>
            <origin rpy="0 0 1.57" xyz="0.0 0.0 0.0"/>
            <geometry>
               <mesh filename="package://harvester/models/arm/gripper.stl" scale="0.001 0.001 0.001"/>
            </geometry>
        </collision>

        <inertial>
            <origin rpy="0 0 1.57" xyz="0.0 0.0 0.0"/>
            <mass value="0.3"/>
            <inertia ixx="0.005" ixy="0" ixz="0" iyy="0.005" iyz="0" izz="0.005"/>
        </inertial>
    </link>

    <gazebo reference="gripper">
        <material>Gazebo/Blue</material>
    </gazebo>

    <joint name="gripper_joint" type="fixed">
        <origin rpy="0 3.14 0" xyz="0 0.18 0"/>
        <child link="gripper"/>
        <parent link="link_2"/>
    </joint>

    <!-- Wheel Left -->
    <link name="left_wheel">
        <visual>
            <origin rpy="0 1.5707 0" xyz="0 0 0"/>
            <geometry>
                <cylinder length="0.02" radius="0.035"/>
            </geometry>
            <material name="black"/>
        </visual>

        <collision>
            <origin rpy="0 1.5707 0" xyz="0 0 0"/>
            <geometry>
                <cylinder length="0.02" radius="0.035"/>
                <!-- <cylinder length="0.06" radius="0.09"/> -->
            </geometry>
        </collision>

        <inertial>
            <origin rpy="0 1.5707 0" xyz="0 0 0"/>
            <mass value="0.1"/>
            <inertia ixx="0.00023250000000000004" ixy="0" ixz="0" iyy="0.00023250000000000004" iyz="0" izz="0.000405"/>
        </inertial>
    </link>
    
    <gazebo reference="left_wheel">
        <kp>100000000000000000000.0</kp>
        <kd>100000000000000000000.0</kd>
        <mu1>10</mu1>
        <mu2>10</mu2>
        <material>Gazebo/Black</material>
    </gazebo>

    <joint name="joint_left_wheel" type="continuous">
        <origin rpy="0 0 0" xyz="0.11 -0.1 -0.02"/>
        <child link="left_wheel"/>
        <parent link="chassis"/>
        <axis rpy="0 0 0" xyz="1 0 0"/>
        <limit effort="10000" velocity="1000"/>
        <joint_properties damping="1.0" friction="1.0"/>
    </joint>

    <!-- Wheel Right -->
    <link name="right_wheel">
        <visual>
            <origin rpy="0 1.5707 0" xyz="0 0 0"/>
            <geometry>
                <cylinder length="0.02" radius="0.035"/>
            </geometry>
            <material name="black"/>
        </visual>

        <collision>
            <origin rpy="0 1.5707 0" xyz="0 0 0"/>
            <geometry>
                <cylinder length="0.02" radius="0.035"/>
            </geometry>
        </collision>

        <inertial>
            <origin rpy="0 1.5707 0" xyz="0 0 0"/>
            <mass value="0.1"/>
            <inertia ixx="3.395833333333334e-05" ixy="0" ixz="0" iyy="0.00023250000000000004" iyz="0" izz="0.000405"/>
        </inertial>
    </link>

    <gazebo reference="right_wheel">
        <kp>100000000000000000000.0</kp>
        <kd>100000000000000000000.0</kd>
        <mu1>10</mu1>
        <mu2>10</mu2>
        <material>Gazebo/Black</material>
    </gazebo>

    <joint name="joint_right_wheel" type="continuous">
        <origin rpy="0 0 0" xyz="-0.11 -0.1 -0.02"/>
        <child link="right_wheel"/>
        <parent link="chassis"/>
        <axis rpy="0 0 0" xyz="1 0 0"/>
        <limit effort="10000" velocity="1000"/>
        <joint_properties damping="1.0" friction="1.0"/>
    </joint>

    <!-- Caster Wheel Back -->
    <link name="back_yaw_link">
        <visual>
            <origin rpy="0 1.5707 1.5707" xyz="0 0 0"/>
            <geometry>
              <cylinder length="0.005" radius="0.025"/>
            </geometry>
            <material name="wooden"/>
        </visual>

        <collision>
            <origin rpy="0 1.5707 1.5707" xyz="0 0 0"/>
            <geometry>
                <cylinder length="0.005" radius="0.025"/>
            </geometry>
        </collision>

        <inertial>
            <origin rpy="0 1.5707 1.5707" xyz="0 0 0"/>
            <mass value="0.01"/>
            <inertia ixx="2.5000000000000004e-07" ixy="0" ixz="0" iyy="2.5000000000000004e-07" iyz="0" izz="2.5000000000000004e-07"/>
        </inertial>
    </link>

    <joint name="back_yaw_joint" type="continuous">
        <origin rpy="0 0 0" xyz="0 0.1 -0.025"/>
        <parent link="chassis" />
        <child link="back_yaw_link" />
        <axis xyz="0 0 1" />
        <limit effort="1000.0" velocity="100.0" />
        <dynamics damping="0.0" friction="0.1"/>
    </joint>

    <gazebo reference="back_yaw_link">
        <material>Gazebo/Purple</material>
    </gazebo>

    <link name="back_roll_link">
        <visual>
            <origin rpy="0 1.5707 1.5707" xyz="0 0 0"/>
            <geometry>
                <cylinder length="0.005" radius="0.025"/>
            </geometry>
            <material name="wooden"/>
        </visual>

        <collision>
            <origin rpy="0 1.5707 1.5707" xyz="0 0 0"/>
            <geometry>
                <cylinder length="0.005" radius="0.025"/>
            </geometry>
        </collision>

        <inertial>
            <origin rpy="0 1.5707 1.5707" xyz="0 0 0"/>
            <mass value="0.01"/>
            <inertia ixx="2.5000000000000004e-07" ixy="0" ixz="0" iyy="2.5000000000000004e-07" iyz="0" izz="2.5000000000000004e-07"/>
        </inertial>
    </link>

    <joint name="back_roll_joint" type="continuous">
        <origin rpy="0 0 0" xyz="0 0 0"/>
        <parent link="back_yaw_link"/>
        <child link="back_roll_link"/>
        <axis xyz="1 0 0" />
        <limit effort="1000.0" velocity="100.0" />
        <dynamics damping="0.0" friction="0.1"/>
    </joint>
        
    <gazebo reference="back_roll_link">
        <material>Gazebo/Purple</material>
    </gazebo>

    <link name="back_pitch_link">
        <visual>
            <origin rpy="0 1.5707 1.5707" xyz="0 0 0"/>
            <geometry>
                <sphere radius="0.025"/>
            </geometry>
            <material name="wooden"/>
        </visual>

        <collision>
            <origin rpy="0 1.5707 1.5707" xyz="0 0 0"/>
            <geometry>
                <sphere radius="0.025"/>
            </geometry>
        </collision>

        <inertial>
            <origin rpy="0 1.5707 1.5707" xyz="0 0 0"/>
            <mass value="0.01"/>
            <inertia ixx="2.5000000000000004e-07" ixy="0" ixz="0" iyy="2.5000000000000004e-07" iyz="0" izz="2.5000000000000004e-07"/>
        </inertial>
    </link>

    <gazebo reference="back_pitch_link">
        <kp>100000000000000.0</kp>
        <kd>100000000000000.0</kd>
        <mu1>0.5</mu1>
        <mu2>0.5</mu2>
        <material>Gazebo/Purple</material>
    </gazebo>

    <joint name="back_pitch_joint" type="continuous">
        <origin rpy="0 0 0" xyz="0 0 0" />
        <parent link="back_roll_link" />
        <child link="back_pitch_link" />
        <axis xyz="0 1 0" />
        <limit effort="1000.0" velocity="100.0" />
        <dynamics damping="0.0" friction="0.1"/>
    </joint>

    <!-- PLUGINS -->
    <!-- JOINT PUBLISHER -->
    <gazebo>
        <plugin name="robocon_jointstates" filename="libgazebo_ros_joint_state_publisher.so">
            <ros>
                <remapping>~/out:=joint_states</remapping>
            </ros>
            <update_rate>30</update_rate>
            <joint_name>link_1_joint</joint_name>
            <joint_name>link_2_joint</joint_name>
            <joint_name>gripper_joint</joint_name>
            <joint_name>arm_base_joint</joint_name>
            <joint_name>joint_left_wheel</joint_name>
            <joint_name>joint_right_wheel</joint_name>
            <joint_name>back_yaw_joint</joint_name>            
            <joint_name>back_roll_joint</joint_name>
            <joint_name>back_pitch_joint</joint_name>
        </plugin>
    </gazebo>

    <gazebo>
        <plugin name="robocon_bot" filename="libgazebo_ros_diff_drive.so">

            <!-- Wheel Information -->
            <update_rate>30</update_rate>
            <left_joint>joint_left_wheel</left_joint>
            <right_joint>joint_right_wheel</right_joint>
            <wheel_separation>0.22</wheel_separation>
            <wheel_diameter>0.07</wheel_diameter>
            <!-- Limits -->
            <max_wheel_torque>10.0</max_wheel_torque>
            <max_wheel_acceleration>10.0</max_wheel_acceleration>
            <!-- Output -->
            <command_topic>cmd_vel</command_topic>
            <publish_odom>true</publish_odom>
            <publish_odom_tf>true</publish_odom_tf>
            <odometry_frame>odom</odometry_frame>
            <robot_base_frame>base_link</robot_base_frame>
            <publish_wheel_tf>true</publish_wheel_tf>
        </plugin>
    </gazebo>

    <ros2_control name="GazeboSystem" type="System">
        <hardware>
            <plugin>gazebo_ros2_control/GazeboSystem</plugin>
        </hardware>
    
        <joint name="link_1_joint">
            <command_interface name="position">
                <param name="min">-3.14</param>
                <param name="max">3.14</param>
            </command_interface>
            <state_interface name="position"/>
            <state_interface name="velocity"/>
        </joint>

        <joint name="link_2_joint">
            <command_interface name="position">
                <param name="min">-3.14</param>
                <param name="max">3.14</param>
            </command_interface>
            <state_interface name="position"/>
            <state_interface name="velocity"/>
        </joint>

    </ros2_control>

    <gazebo>
        <plugin filename="libgazebo_ros2_control.so" name="gazebo_ros2_control">
            <parameters>$(find harvester)/config/arm_controller.yaml</parameters>
            <robot_param_node>robot_state_publisher_node</robot_param_node>
        </plugin>
    </gazebo>  

</robot>
